<?xml version="1.0" encoding="UTF-8"?>
<testng-results skipped="0" failed="1" ignored="0" total="1" passed="0">
  <reporter-output>
  </reporter-output>
  <suite name="Default suite" duration-ms="63478" started-at="2019-07-21T03:08:43Z" finished-at="2019-07-21T03:09:46Z">
    <groups>
    </groups>
    <test name="Default test" duration-ms="63478" started-at="2019-07-21T03:08:43Z" finished-at="2019-07-21T03:09:46Z">
      <class name="Myntra_ReportDemo.AppsMainMethod">
        <test-method status="FAIL" signature="myTestCases()[pri:0, instance:Myntra_ReportDemo.AppsMainMethod@457e2f02]" name="myTestCases" duration-ms="55947" started-at="2019-07-21T03:08:43Z" finished-at="2019-07-21T03:09:39Z">
          <exception class="java.lang.AssertionError">
            <message>
              <![CDATA[expected [20] but found [10]]]>
            </message>
            <full-stacktrace>
              <![CDATA[java.lang.AssertionError: expected [20] but found [10]
at org.testng.Assert.fail(Assert.java:96)
at org.testng.Assert.failNotEquals(Assert.java:776)
at org.testng.Assert.assertEqualsImpl(Assert.java:137)
at org.testng.Assert.assertEquals(Assert.java:118)
at org.testng.Assert.assertEquals(Assert.java:652)
at org.testng.Assert.assertEquals(Assert.java:662)
at Myntra_ReportDemo.AppsMainMethod.myTestCases(AppsMainMethod.java:29)
at sun.reflect.NativeMethodAccessorImpl.invoke0(Native Method)
at sun.reflect.NativeMethodAccessorImpl.invoke(Unknown Source)
at sun.reflect.DelegatingMethodAccessorImpl.invoke(Unknown Source)
at java.lang.reflect.Method.invoke(Unknown Source)
at org.testng.internal.MethodInvocationHelper.invokeMethod(MethodInvocationHelper.java:124)
at org.testng.internal.Invoker.invokeMethod(Invoker.java:583)
at org.testng.internal.Invoker.invokeTestMethod(Invoker.java:719)
at org.testng.internal.Invoker.invokeTestMethods(Invoker.java:989)
at org.testng.internal.TestMethodWorker.invokeTestMethods(TestMethodWorker.java:125)
at org.testng.internal.TestMethodWorker.run(TestMethodWorker.java:109)
at org.testng.TestRunner.privateRun(TestRunner.java:648)
at org.testng.TestRunner.run(TestRunner.java:505)
at org.testng.SuiteRunner.runTest(SuiteRunner.java:455)
at org.testng.SuiteRunner.runSequentially(SuiteRunner.java:450)
at org.testng.SuiteRunner.privateRun(SuiteRunner.java:415)
at org.testng.SuiteRunner.run(SuiteRunner.java:364)
at org.testng.SuiteRunnerWorker.runSuite(SuiteRunnerWorker.java:52)
at org.testng.SuiteRunnerWorker.run(SuiteRunnerWorker.java:84)
at org.testng.TestNG.runSuitesSequentially(TestNG.java:1208)
at org.testng.TestNG.runSuitesLocally(TestNG.java:1137)
at org.testng.TestNG.runSuites(TestNG.java:1049)
at org.testng.TestNG.run(TestNG.java:1017)
at org.testng.remote.AbstractRemoteTestNG.run(AbstractRemoteTestNG.java:114)
at org.testng.remote.RemoteTestNG.initAndRun(RemoteTestNG.java:251)
at org.testng.remote.RemoteTestNG.main(RemoteTestNG.java:77)
]]>
            </full-stacktrace>
          </exception> <!-- java.lang.AssertionError -->
          <reporter-output>
          </reporter-output>
        </test-method> <!-- myTestCases -->
        <test-method status="PASS" signature="myCodeFailureCase(org.testng.ITestResult)[pri:0, instance:Myntra_ReportDemo.AppsMainMethod@457e2f02]" name="myCodeFailureCase" is-config="true" duration-ms="7146" started-at="2019-07-21T03:09:39Z" finished-at="2019-07-21T03:09:46Z">
          <params>
            <param index="0">
              <value>
                <![CDATA[[TestResult name=myTestCases status=FAILURE method=AppsMainMethod.myTestCases()[pri:0, instance:Myntra_ReportDemo.AppsMainMethod@457e2f02] output={null}]]]>
              </value>
            </param>
          </params>
          <reporter-output>
          </reporter-output>
        </test-method> <!-- myCodeFailureCase -->
      </class> <!-- Myntra_ReportDemo.AppsMainMethod -->
    </test> <!-- Default test -->
  </suite> <!-- Default suite -->
</testng-results>
